<?xml version="1.0"?>

<robot name="scout_mini" xmlns:xacro="http://ros.org/wiki/xacro">
    <!-- Vehicle Geometries -->
    <!-- Base link -->
    <link name="base_link">
        <visual>
            <origin xyz="0 0 0" rpy="1.57 0 -1.57" />
            <geometry>
                <mesh
                    filename="package://scout_description/meshes/scout_mini_base_link.dae" />
            </geometry>
        </visual>
        <collision>
            <origin xyz="0 0 0" rpy="1.57 0 -1.57" />
            <geometry>
                <mesh
                    filename="package://scout_description/meshes/scout_mini_base_link.dae" />
            </geometry>
        </collision>
    </link>

    <link
        name="inertial_link">
        <inertial>
            <mass value="132.3898489950015" />
            <origin xyz=" 0 0 0" />
            <inertia ixx="0.185196122711036" ixy="4.30144213829512E-08" ixz="5.81037523686401E-08"
                iyy="0.364893736238929" iyz="-0.000386720198091934" izz="0.223868521722778" />
        </inertial>
    </link>

    <joint
        name="inertial_joint" type="fixed">
        <origin xyz="0 0 0" rpy="0 0 0" />
        <parent link="base_link" />
        <child link="inertial_link" />
    </joint>

    <!-- Scout wheel -->
    <link
        name="front_right_wheel_link">
        <inertial>
            <mass value="3" />
            <origin xyz="0 0 0" />
            <inertia ixx="0.7171" ixy="0" ixz="0" iyy="0.7171" iyz="0" izz="0.1361" />
        </inertial>
        <visual>
            <origin xyz="0 0 0" rpy="0 0 0" />
            <geometry>
                <mesh filename="package://scout_description/meshes/wheel.dae" />
            </geometry>
        </visual>
        <collision>
            <origin xyz="0 0 0" rpy="0 0 0" />
            <geometry>
                <mesh filename="package://scout_description/meshes/wheel.dae" />
            </geometry>
        </collision>
    </link>

    <joint
        name="front_right_wheel" type="continuous">
        <origin rpy="1.57 0 0" xyz="0.2319755 -0.2082515 -0.099998" />
        <parent link="base_link" />
        <child link="front_right_wheel_link" />
        <axis xyz="0 0 -1" rpy="0 0 0" />
    </joint>

    <link name="front_left_wheel_link">
        <inertial>
            <mass value="3" />
            <origin xyz="0 0 0" />
            <inertia ixx="0.7171" ixy="0" ixz="0" iyy="0.7171" iyz="0" izz="0.1361" />
        </inertial>
        <visual>
            <origin xyz="0 0 0" rpy="0 0 0" />
            <geometry>
                <mesh filename="package://scout_description/meshes/wheel.dae" />
            </geometry>
        </visual>
        <collision>
            <origin xyz="0 0 0" rpy="0 0 0" />
            <geometry>
                <mesh filename="package://scout_description/meshes/wheel.dae" />
            </geometry>
        </collision>
    </link>

    <joint
        name="front_left_wheel" type="continuous">
        <origin rpy="-1.57 0 0" xyz="0.2319755 0.2082515 -0.100998" />
        <parent link="base_link" />
        <child link="front_left_wheel_link" />
        <axis xyz="0 0 1" rpy="0 0 0" />
    </joint>

    <link name="rear_right_wheel_link">
        <inertial>
            <mass value="3" />
            <origin xyz="0 0 0" />
            <inertia ixx="0.7171" ixy="0" ixz="0" iyy="0.7171" iyz="0" izz="0.1361" />
        </inertial>
        <visual>
            <origin xyz="0 0 0" rpy="0 0 0" />
            <geometry>
                <mesh filename="package://scout_description/meshes/wheel.dae" />
            </geometry>
        </visual>
        <collision>
            <origin xyz="0 0 0" rpy="0 0 0" />
            <geometry>
                <mesh filename="package://scout_description/meshes/wheel.dae" />
            </geometry>
        </collision>
    </link>

    <joint
        name="rear_right_wheel" type="continuous">
        <origin rpy="1.57 0 0" xyz="-0.2319755 -0.2082515 -0.099998" />
        <parent link="base_link" />
        <child link="rear_right_wheel_link" />
        <axis xyz="0 0 -1" rpy="0 0 0" />
    </joint>

    <link name="rear_left_wheel_link">
        <inertial>
            <mass value="3" />
            <origin xyz="0 0 0" />
            <inertia ixx="0.7171" ixy="0" ixz="0" iyy="0.7171" iyz="0" izz="0.1361" />
        </inertial>
        <visual>
            <origin xyz="0 0 0" rpy="0 0 0" />
            <geometry>
                <mesh filename="package://scout_description/meshes/wheel.dae" />
            </geometry>
        </visual>
        <collision>
            <origin xyz="0 0 0" rpy="0 0 0" />
            <geometry>
                <mesh filename="package://scout_description/meshes/wheel.dae" />
            </geometry>
        </collision>
    </link>

    <joint
        name="rear_left_wheel" type="continuous">
        <origin rpy="-1.57 0 0" xyz="-0.2319755 0.2082515 -0.100998" />
        <parent link="base_link" />
        <child link="rear_left_wheel_link" />
        <axis xyz="0 0 1" rpy="0 0 0" />
    </joint>
    <!-- Lidar init-->
    <link name="lidar_link">
        <visual>
            <geometry>
                <cylinder radius="0.05" length="0.02" />
            </geometry>
            <material>
                <color rgba="0.0 1.0 0.0 1.0" />
            </material>
        </visual>
        <collision>
            <geometry>
                <cylinder radius="0.05" length="0.02" />
            </geometry>
        </collision>
        <inertial>
            <mass value="0.1" />
            <origin xyz="0 0 0" />
            <inertia ixx="0.001" iyy="0.001" izz="0.001" ixy="0" ixz="0" iyz="0" />
        </inertial>
    </link>

    <joint name="lidar_joint" type="fixed">
        <parent link="base_link" />
        <child link="lidar_link" />
        <origin xyz="0 0 0.2" rpy="0 0 0" />
    </joint>

    <!-- <gazebo reference="lidar_link">
        <sensor type="ray" name="lidar_sensor">
            <update_rate>10</update_rate>
            <ray>
                <scan>
                    <horizontal>
                        <samples>720</samples>
                        <resolution>1.0</resolution>
                        <min_angle>-1.57</min_angle>
                        <max_angle>1.57</max_angle>
                    </horizontal>
                </scan>
                <range>
                    <min>0.1</min>
                    <max>10.0</max>
                    <resolution>0.01</resolution>
                </range>
            </ray>
            <plugin filename="libgz-sim-sensors-system.so" name="gz::sim::systems::Sensors">
                <render_engine>ogre2</render_engine>
            </plugin>
        </sensor>
    </gazebo> -->
    <gazebo reference="lidar_link">
        <sensor name="lidar_sensor" type="gpu_lidar">
            <pose> 0 0 0 0 0 0 </pose>
            <always_on>true</always_on>
            <visualize>true</visualize>
            <update_rate>10</update_rate>
            <topic>/scout_mini/scan</topic>
            <gz_frame_id>lidar_link</gz_frame_id>
            <lidar>
                <scan>
                    <horizontal>
                        <samples>360</samples>
                        <min_angle>-3.14</min_angle>
                        <max_angle>3.14</max_angle>
                    </horizontal>
                </scan>
                <range>
                    <min>0.3</min>
                    <max>12</max>
                </range>
            </lidar>
        </sensor>
    </gazebo>
    <!-- Lidar end-->

    <!-- Scout gazebo plugin -->
    <gazebo>
        <plugin filename="libgz-sim-joint-state-publisher-system.so"
            name="gz::sim::systems::JointStatePublisher">
            <topic>joint_states</topic>

            <update_rate>50</update_rate>

            <joint_name>front_right_wheel</joint_name>
            <joint_name>front_left_wheel</joint_name>
            <joint_name>rear_right_wheel</joint_name>
            <joint_name>rear_left_wheel</joint_name>
        </plugin>

        <plugin
            filename="libgz-sim-diff-drive-system.so"
            name="gz::sim::systems::DiffDrive">

            <left_joint>front_left_wheel</left_joint>
            <right_joint>front_right_wheel</right_joint>
            <left_joint>rear_left_wheel</left_joint>
            <right_joint>rear_right_wheel</right_joint>

            <wheel_separation>0.490</wheel_separation>
            <wheel_radius>0.160</wheel_radius>

            <!-- limits -->
            <max_wheel_torque>20</max_wheel_torque>
            <max_linear_acceleration>1.0</max_linear_acceleration>

            <!-- Plugin settings -->
            <topic>cmd_vel</topic>
            <odom_topic>odom</odom_topic>
            <tf_topic>tf</tf_topic>
            <odom_publish_frequency>50</odom_publish_frequency>

            <frame_id>odom</frame_id>
            <child_frame_id>base_link</child_frame_id>
        </plugin>
    </gazebo>
</robot>