<?xml version="1.0"?>

<robot name="scout_mini" xmlns:xacro="http://ros.org/wiki/xacro">
    <!-- Vehicle Geometries -->
    <!-- Base link -->
    <link name="base_link">
        <visual>
            <origin xyz="0 0 0" rpy="1.57 0 -1.57" />
            <geometry>
                <mesh
                    filename="package://scout_description/meshes/scout_mini_base_link.dae" />
            </geometry>
        </visual>
        <collision>
            <origin xyz="0 0 0" rpy="1.57 0 -1.57" />
            <geometry>
                <mesh
                    filename="package://scout_description/meshes/scout_mini_base_link.dae" />
            </geometry>
        </collision>
    </link>

    <link
        name="inertial_link">
        <inertial>
            <mass value="132.3898489950015" />
            <origin xyz=" 0 0 0" />
            <inertia ixx="0.185196122711036" ixy="4.30144213829512E-08" ixz="5.81037523686401E-08"
                iyy="0.364893736238929" iyz="-0.000386720198091934" izz="0.223868521722778" />
        </inertial>
    </link>

    <joint
        name="inertial_joint" type="fixed">
        <origin xyz="0 0 0" rpy="0 0 0" />
        <parent link="base_link" />
        <child link="inertial_link" />
    </joint>

    <!-- Scout wheel -->
    <link
        name="front_right_wheel_link">
        <inertial>
            <mass value="3" />
            <origin xyz="0 0 0" />
            <inertia ixx="0.7171" ixy="0" ixz="0" iyy="0.7171" iyz="0" izz="0.1361" />
        </inertial>
        <visual>
            <origin xyz="0 0 0" rpy="0 0 0" />
            <geometry>
                <mesh filename="package://scout_description/meshes/wheel.dae" />
            </geometry>
        </visual>
        <collision>
            <origin xyz="0 0 0" rpy="0 0 0" />
            <geometry>
                <mesh filename="package://scout_description/meshes/wheel.dae" />
            </geometry>
        </collision>
    </link>

    <joint
        name="front_right_wheel" type="continuous">
        <origin rpy="1.57 0 0" xyz="0.2319755 -0.2082515 -0.099998" />
        <parent link="base_link" />
        <child link="front_right_wheel_link" />
        <axis xyz="0 0 -1" rpy="0 0 0" />
    </joint>

    <link name="front_left_wheel_link">
        <inertial>
            <mass value="3" />
            <origin xyz="0 0 0" />
            <inertia ixx="0.7171" ixy="0" ixz="0" iyy="0.7171" iyz="0" izz="0.1361" />
        </inertial>
        <visual>
            <origin xyz="0 0 0" rpy="0 0 0" />
            <geometry>
                <mesh filename="package://scout_description/meshes/wheel.dae" />
            </geometry>
        </visual>
        <collision>
            <origin xyz="0 0 0" rpy="0 0 0" />
            <geometry>
                <mesh filename="package://scout_description/meshes/wheel.dae" />
            </geometry>
        </collision>
    </link>

    <joint
        name="front_left_wheel" type="continuous">
        <origin rpy="-1.57 0 0" xyz="0.2319755 0.2082515 -0.100998" />
        <parent link="base_link" />
        <child link="front_left_wheel_link" />
        <axis xyz="0 0 1" rpy="0 0 0" />
    </joint>

    <link name="rear_right_wheel_link">
        <inertial>
            <mass value="3" />
            <origin xyz="0 0 0" />
            <inertia ixx="0.7171" ixy="0" ixz="0" iyy="0.7171" iyz="0" izz="0.1361" />
        </inertial>
        <visual>
            <origin xyz="0 0 0" rpy="0 0 0" />
            <geometry>
                <mesh filename="package://scout_description/meshes/wheel.dae" />
            </geometry>
        </visual>
        <collision>
            <origin xyz="0 0 0" rpy="0 0 0" />
            <geometry>
                <mesh filename="package://scout_description/meshes/wheel.dae" />
            </geometry>
        </collision>
    </link>

    <joint
        name="rear_right_wheel" type="continuous">
        <origin rpy="1.57 0 0" xyz="-0.2319755 -0.2082515 -0.099998" />
        <parent link="base_link" />
        <child link="rear_right_wheel_link" />
        <axis xyz="0 0 -1" rpy="0 0 0" />
    </joint>

    <link name="rear_left_wheel_link">
        <inertial>
            <mass value="3" />
            <origin xyz="0 0 0" />
            <inertia ixx="0.7171" ixy="0" ixz="0" iyy="0.7171" iyz="0" izz="0.1361" />
        </inertial>
        <visual>
            <origin xyz="0 0 0" rpy="0 0 0" />
            <geometry>
                <mesh filename="package://scout_description/meshes/wheel.dae" />
            </geometry>
        </visual>
        <collision>
            <origin xyz="0 0 0" rpy="0 0 0" />
            <geometry>
                <mesh filename="package://scout_description/meshes/wheel.dae" />
            </geometry>
        </collision>
    </link>

    <joint
        name="rear_left_wheel" type="continuous">
        <origin rpy="-1.57 0 0" xyz="-0.2319755 0.2082515 -0.100998" />
        <parent link="base_link" />
        <child link="rear_left_wheel_link" />
        <axis xyz="0 0 1" rpy="0 0 0" />
    </joint>
    <!-- Lidar init-->
    <link name="lidar_link">
        <inertial>
            <mass value="0.1" />
            <origin xyz="0 0 0" />
            <inertia ixx="0.001" iyy="0.001" izz="0.001" ixy="0" ixz="0" iyz="0" />
        </inertial>
        <visual>
            <origin xyz="0 0 -0.02" rpy="0 0 0" />
            <geometry>
                <cylinder radius="0.05" length="0.1" />
            </geometry>
            <material name="white">
                <color rgba="1 1 1 1" />
            </material>
        </visual>
        <collision>
            <origin xyz="-0 0 -0.02" rpy="0 0 0" />
            <geometry>
                <cylinder radius="0.05" length="0.1" />
            </geometry>
        </collision>
    </link>

    <joint name="lidar_joint" type="fixed">
        <parent link="base_link" />
        <child link="lidar_link" />
        <origin xyz="0 0 0.1" rpy="0 0 0" />
    </joint>
    <gazebo reference="lidar_link">
        <sensor name="lidar_sensor" type="gpu_ray">
            <pose> 0 0 0 0 0 0 </pose>
            <always_on>true</always_on>
            <visualize>true</visualize>
            <update_rate>10</update_rate>
            <topic>/scout_mini/scan</topic>
            <gz_frame_id>lidar_link</gz_frame_id>
            <lidar>
                <scan>
                    <horizontal>
                        <samples>360</samples>
                        <min_angle>0</min_angle>
                        <max_angle>6.28</max_angle>
                    </horizontal>
                    <vertical>
                        <samples>16</samples>
                        <min_angle>-0.262</min_angle>
                        <max_angle>0.523</max_angle>
                    </vertical>
                </scan>
                <range>
                    <min>0.3</min>
                    <max>12</max>
                </range>
            </lidar>
        </sensor>
    </gazebo>
    <!-- Lidar end-->

    <!-- RGB cam start-->
    <link name="camera_link">
        <inertial>
            <mass value="0.1" />
            <origin xyz="0 0 0" />
            <inertia ixx="0.001" iyy="0.001" izz="0.001" ixy="0" ixz="0" iyz="0" />
        </inertial>
        <visual>
            <origin xyz="0 0 0" rpy="0 0 0" />
            <geometry>
                <box size="0.05 0.05 0.05" />
            </geometry>
            <material name="white">
                <color rgba="1 1 1 1" />
            </material>
        </visual>
        <collision>
            <origin xyz="0 0 0" rpy="0 0 0" />
            <geometry>
                <box size="0.05 0.05 0.05" />
            </geometry>
        </collision>
    </link>
    <joint name="camera_joint" type="fixed">
        <parent link="base_link" />
        <child link="camera_link" />
        <origin xyz="0.18 0 0.05" rpy="0 0 0" />
    </joint>
    <gazebo reference="camera_link">
        <sensor name="rgb_cam" type="camera">
            <always_on>1</always_on>
            <update_rate>60</update_rate>
            <visualize>1</visualize>
            <pose>0 0.0175 0.5125 0 0 0</pose>
            <topic>scout_mini/rgb_cam/image_raw</topic>
            <camera name="rgb_cam">
                <horizontal_fov>1.21126</horizontal_fov>
                <image>
                    <width>640</width>
                    <height>480</height>
                    <format>RGB_INT8</format>
                </image>
                <clip>
                    <near>0.1</near>
                    <far>100</far>
                </clip>
                <noise>
                    <type>gaussian</type>
                    <mean>0</mean>
                    <stddev>0.007</stddev>
                </noise>
            </camera>
        </sensor>
    </gazebo>


    <!-- Scout gazebo plugin -->
    <gazebo>
        <plugin filename="libgz-sim-joint-state-publisher-system.so"
            name="gz::sim::systems::JointStatePublisher">
            <topic>joint_states</topic>

            <update_rate>50</update_rate>

            <joint_name>front_right_wheel</joint_name>
            <joint_name>front_left_wheel</joint_name>
            <joint_name>rear_right_wheel</joint_name>
            <joint_name>rear_left_wheel</joint_name>
        </plugin>

        <plugin
            filename="libgz-sim-diff-drive-system.so"
            name="gz::sim::systems::DiffDrive">

            <left_joint>front_left_wheel</left_joint>
            <right_joint>front_right_wheel</right_joint>
            <left_joint>rear_left_wheel</left_joint>
            <right_joint>rear_right_wheel</right_joint>

            <wheel_separation>0.490</wheel_separation>
            <wheel_radius>0.160</wheel_radius>

            <!-- limits -->
            <max_wheel_torque>20</max_wheel_torque>
            <max_linear_acceleration>1.0</max_linear_acceleration>

            <!-- Plugin settings -->
            <topic>cmd_vel</topic>
            <odom_topic>odom</odom_topic>
            <tf_topic>tf</tf_topic>
            <odom_publish_frequency>50</odom_publish_frequency>

            <frame_id>odom</frame_id>
            <child_frame_id>base_link</child_frame_id>
        </plugin>
    </gazebo>
</robot>